<?xml version="1.0"?>

<robot name="kou_rover"> 

    <material name="darkgrey">
        <color rgba="0.169 0.169 0.169 1" />
    </material>
    <material name="lightgrey">
        <color rgba="0.64 0.64 0.64 1" />
    </material>
    <material name="red">
        <color rgba="1 0 0" />
    </material>

    <link name="base_link">
        <visual>
            <geometry>
                <box size="0.75 0.88 0.48"/>
            </geometry>
            <origin xyz="0 0 0.365" rpy="0 0 0" />
            <material name="darkgrey" />
        </visual>
    </link>

    <link name="right_wheel_link">
        <visual>
            <geometry>
                <cylinder radius="0.125" length="0.03" />
            </geometry>
            <origin xyz="0 0 0.0125" rpy="0 0 0" />
            <material name="lightgrey" />

        </visual>
    </link>

    <link name="left_wheel_link">
        <visual>
            <geometry>
                <cylinder radius="0.125" length="0.03"/>
            </geometry>
            <origin xyz="0 0 0.0125" rpy="0 0 0 "/>
            <material name="lightgrey" />
        </visual>
    </link>

    <link name="caster1_wheel_link">
        <visual>
            <geometry>
                <sphere radius="0.0625" />
            </geometry>
            <origin xyz="0 0 0" rpy="0 0 0 "/>
            <material name="red" />
        </visual>
    </link>


    <link name="caster2_wheel_link">
        <visual>
            <geometry>
                <sphere radius="0.0625" />
            </geometry>
            <origin xyz="0 0 0" rpy="0 0 0 "/>
            <material name="red" />
        </visual>
    </link>


    <link name="caster3_wheel_link">
        <visual>
            <geometry>
                <sphere radius="0.0625" />
            </geometry>
            <origin xyz="0 0 0" rpy="0 0 0 "/>
            <material name="red" />
        </visual>
    </link>

    <link name="caster4_wheel_link">
        <visual>
            <geometry>
                <sphere radius="0.0625" />
            </geometry>
            <origin xyz="0 0 0" rpy="0 0 0 "/>
            <material name="red" />
        </visual>
    </link>

    








    <joint name="base_rwheel_joint" type="continuous">
        <parent link="base_link" />
        <child link="right_wheel_link" />
        <origin xyz="0.38 0 0.125" rpy="0 1.57 0" />
        <axis xyz="0 0 1" />
    </joint>


    <joint name="base_lwheel_joint" type="continuous">
        <parent link="base_link" />
        <child link="left_wheel_link" />
        <origin xyz="-0.408 0 0.125" rpy="0 1.57 0" />
        <axis xyz="0 0 1" />
    </joint>


    <joint name="base_caster1_joint" type="fixed">
        <parent link="base_link" />
        <child link="caster1_wheel_link" />
        <origin xyz="0.335 -0.4 0.0625" rpy="0 0 0" />
    </joint>


    <joint name="base_caster2_joint" type="fixed">
        <parent link="base_link" />
        <child link="caster2_wheel_link" />
        <origin xyz="-0.335 -0.4 0.0625" rpy="0 0 0" />
    </joint>

    <joint name="base_caster3_joint" type="fixed">
        <parent link="base_link" />
        <child link="caster3_wheel_link" />
        <origin xyz="0.335 0.4 0.0625" rpy="0 0 0" />
    </joint>

    <joint name="base_caster4_joint" type="fixed">
        <parent link="base_link" />
        <child link="caster4_wheel_link" />
        <origin xyz="-0.335 0.4 0.0625" rpy="0 0 0" />
    </joint>


    

    

</robot>
