<?xml version="1.0"?>
<robot xmlns:xacro="http://www.ros.org/wiki/xacro"> 

    <xacro:property name="base_length" value="0.75" /> 
    <xacro:property name="base_width" value="0.88" />
    <xacro:property name="base_height" value="0.48" />

    


    <link name="base_footprint" />


    <link name="base_link">
        <visual>
            <geometry>
                <box size="${base_length} ${base_width} ${base_height}"/>
            </geometry>
            <origin xyz="0 0 0.365" rpy="0 0 0" />
            <material name="darkgrey" />
        </visual>
    </link>

    <xacro:macro name="wheel_link" params="prefix"> 
        <link name="${prefix}_wheel_link">
            <visual>
                <geometry>
                    <cylinder radius="0.125" length="0.03" />
                </geometry>
                <origin xyz="0 0 0.0125" rpy="0 0 0" />
                <material name="lightgrey" />

            </visual>   
        </link>
    </xacro:macro>

    <xacro:wheel_link prefix="right" />
    <xacro:wheel_link prefix="left" />        


    

    <link name="caster1_wheel_link">
        <visual>
            <geometry>
                <sphere radius="0.0625" />
            </geometry>
            <origin xyz="0 0 0" rpy="0 0 0 "/>
            <material name="red" />
        </visual>
    </link>


    <link name="caster2_wheel_link">
        <visual>
            <geometry>
                <sphere radius="0.0625" />
            </geometry>
            <origin xyz="0 0 0" rpy="0 0 0 "/>
            <material name="red" />
        </visual>
    </link>


    <link name="caster3_wheel_link">
        <visual>
            <geometry>
                <sphere radius="0.0625" />
            </geometry>
            <origin xyz="0 0 0" rpy="0 0 0 "/>
            <material name="red" />
        </visual>
    </link>

    <link name="caster4_wheel_link">
        <visual>
            <geometry>
                <sphere radius="0.0625" />
            </geometry>
            <origin xyz="0 0 0" rpy="0 0 0 "/>
            <material name="red" />
        </visual>
    </link>

    






    <joint name="base_joint" type="fixed">
        <parent link="base_footprint" />
        <child link="base_link" />
        <origin xyz="0 0 0" rpy="0 0 0"/>
    </joint>


    <joint name="base_rwheel_joint" type="continuous">
        <parent link="base_link" />
        <child link="right_wheel_link" />
        <origin xyz="0.38 0 0.125" rpy="0 ${pi / 2.0} 0" />
        <axis xyz="0 0 1" />
    </joint>


    <joint name="base_lwheel_joint" type="continuous">
        <parent link="base_link" />
        <child link="left_wheel_link" />
        <origin xyz="-0.408 0 0.125" rpy="0 ${pi / 2.0} 0" />
        <axis xyz="0 0 1" />
    </joint>


    <joint name="base_caster1_joint" type="fixed">
        <parent link="base_link" />
        <child link="caster1_wheel_link" />
        <origin xyz="0.335 -0.4 0.0625" rpy="0 0 0" />
    </joint>


    <joint name="base_caster2_joint" type="fixed">
        <parent link="base_link" />
        <child link="caster2_wheel_link" />
        <origin xyz="-0.335 -0.4 0.0625" rpy="0 0 0" />
    </joint>

    <joint name="base_caster3_joint" type="fixed">
        <parent link="base_link" />
        <child link="caster3_wheel_link" />
        <origin xyz="0.335 0.4 0.0625" rpy="0 0 0" />
    </joint>

    <joint name="base_caster4_joint" type="fixed">
        <parent link="base_link" />
        <child link="caster4_wheel_link" />
        <origin xyz="-0.335 0.4 0.0625" rpy="0 0 0" />
    </joint>

</robot>
